A new study created in memory with name: no-name-43b5c568-984d-4936-9bb8-a21d8374819e
Trial 0 failed with parameters: {'n_estimators': 17, 'min_samples_leaf': 0.19325882509735576, 'max_features': 'sqrt'} because of the following error: TypeError("initialize_transformer_series() got an unexpected keyword argument 'series_col_names'").
Traceback (most recent call last):
  File "C:\anaconda\envs\skforecast_14_p12\Lib\site-packages\optuna\study\_optimize.py", line 196, in _run_trial
    value_or_values = func(trial)
                      ^^^^^^^^^^^
  File "C:\Users\Joaquín Amat\Documents\GitHub\skforecast\skforecast\model_selection_multiseries\model_selection_multiseries.py", line 2426, in _objective
    metrics, _ = backtesting_forecaster_multiseries(
                 ^^^^^^^^^^^^^^^^^^^^^^^^^^^^^^^^^^^
  File "C:\Users\Joaquín Amat\Documents\GitHub\skforecast\skforecast\model_selection_multiseries\model_selection_multiseries.py", line 1290, in backtesting_forecaster_multiseries
    metrics_levels, backtest_predictions = _backtesting_forecaster_multiseries(
                                           ^^^^^^^^^^^^^^^^^^^^^^^^^^^^^^^^^^^^
  File "C:\Users\Joaquín Amat\Documents\GitHub\skforecast\skforecast\model_selection_multiseries\model_selection_multiseries.py", line 942, in _backtesting_forecaster_multiseries
    forecaster.fit(
  File "C:\Users\Joaquín Amat\Documents\GitHub\skforecast\skforecast\ForecasterAutoregMultiSeriesCustom\ForecasterAutoregMultiSeriesCustom.py", line 1203, in fit
    ) = self._create_train_X_y(
        ^^^^^^^^^^^^^^^^^^^^^^^
  File "C:\Users\Joaquín Amat\Documents\GitHub\skforecast\skforecast\ForecasterAutoregMultiSeriesCustom\ForecasterAutoregMultiSeriesCustom.py", line 749, in _create_train_X_y
    self.transformer_series_ = initialize_transformer_series(
                               ^^^^^^^^^^^^^^^^^^^^^^^^^^^^^^
TypeError: initialize_transformer_series() got an unexpected keyword argument 'series_col_names'
Trial 0 failed with value None.
